Workbook

Sheet Dashboard
A1: Service Weekly KT — Interactive Dashboard
A3: Total Tasks | C3: Completed | E3: In Process | G3: New / Pending | I3: Completion %
A4: =COUNTA(Tasks!B2:B1000) | C4: =COUNTIF(Tasks!G2:G1000,"Done") | E4: =COUNTIF(Tasks!G2:G1000,"In process") | G4: =COUNTIF(Tasks!G2:G1000,"New") | I4: =IFERROR(COUNTIF(Tasks!G2:G1000,"Done")/COUNTA(Tasks!B2:B1000),0)
A7: Status Breakdown
A8: Status | B8: Count | C8: Share
A9: Done | B9: =COUNTIF(Tasks!G2:G1000,"Done") | C9: =IFERROR(B9/SUM($B$9:$B$11),0)
A10: In process | B10: =COUNTIF(Tasks!G2:G1000,"In process") | C10: =IFERROR(B10/SUM($B$9:$B$11),0)
A11: New | B11: =COUNTIF(Tasks!G2:G1000,"New") | C11: =IFERROR(B11/SUM($B$9:$B$11),0)
A16: Employee Performance
A17: PIC | B17: Total | C17: Done | D17: In Process | E17: New | F17: Completion %
A18: Ahad | B18: =COUNTIF(Tasks!D2:D1000,A18) | C18: =COUNTIFS(Tasks!D2:D1000,A18,Tasks!G2:G1000,"Done") | D18: =COUNTIFS(Tasks!D2:D1000,A18,Tasks!G2:G1000,"In process") | E18: =COUNTIFS(Tasks!D2:D1000,A18,Tasks!G2:G1000,"New") | F18: =IFERROR(C18/B18,0)
A19: Arslan | B19: =COUNTIF(Tasks!D2:D1000,A19) | C19: =COUNTIFS(Tasks!D2:D1000,A19,Tasks!G2:G1000,"Done") | D19: =COUNTIFS(Tasks!D2:D1000,A19,Tasks!G2:G1000,"In process") | E19: =COUNTIFS(Tasks!D2:D1000,A19,Tasks!G2:G1000,"New") | F19: =IFERROR(C19/B19,0)
A20: Moahed | B20: =COUNTIF(Tasks!D2:D1000,A20) | C20: =COUNTIFS(Tasks!D2:D1000,A20,Tasks!G2:G1000,"Done") | D20: =COUNTIFS(Tasks!D2:D1000,A20,Tasks!G2:G1000,"In process") | E20: =COUNTIFS(Tasks!D2:D1000,A20,Tasks!G2:G1000,"New") | F20: =IFERROR(C20/B20,0)
A21: Moahed - Victory | B21: =COUNTIF(Tasks!D2:D1000,A21) | C21: =COUNTIFS(Tasks!D2:D1000,A21,Tasks!G2:G1000,"Done") | D21: =COUNTIFS(Tasks!D2:D1000,A21,Tasks!G2:G1000,"In process") | E21: =COUNTIFS(Tasks!D2:D1000,A21,Tasks!G2:G1000,"New") | F21: =IFERROR(C21/B21,0)
A22: Victory | B22: =COUNTIF(Tasks!D2:D1000,A22) | C22: =COUNTIFS(Tasks!D2:D1000,A22,Tasks!G2:G1000,"Done") | D22: =COUNTIFS(Tasks!D2:D1000,A22,Tasks!G2:G1000,"In process") | E22: =COUNTIFS(Tasks!D2:D1000,A22,Tasks!G2:G1000,"New") | F22: =IFERROR(C22/B22,0)
A25: Tasks by Module
A26: Module | B26: Total | C26: Done | D26: Open
A27: CC | B27: =COUNTIF(Tasks!B2:B1000,A27) | C27: =COUNTIFS(Tasks!B2:B1000,A27,Tasks!G2:G1000,"Done") | D27: =B27-C27
A28: IT | B28: =COUNTIF(Tasks!B2:B1000,A28) | C28: =COUNTIFS(Tasks!B2:B1000,A28,Tasks!G2:G1000,"Done") | D28: =B28-C28
A29: Qulity | B29: =COUNTIF(Tasks!B2:B1000,A29) | C29: =COUNTIFS(Tasks!B2:B1000,A29,Tasks!G2:G1000,"Done") | D29: =B29-C29
A30: SN | B30: =COUNTIF(Tasks!B2:B1000,A30) | C30: =COUNTIFS(Tasks!B2:B1000,A30,Tasks!G2:G1000,"Done") | D30: =B30-C30
A31: SP | B31: =COUNTIF(Tasks!B2:B1000,A31) | C31: =COUNTIFS(Tasks!B2:B1000,A31,Tasks!G2:G1000,"Done") | D31: =B31-C31
A32: TEC | B32: =COUNTIF(Tasks!B2:B1000,A32) | C32: =COUNTIFS(Tasks!B2:B1000,A32,Tasks!G2:G1000,"Done") | D32: =B32-C32
A35: Weekly Trend — Status Mix & Completion %
A36: Week | B36: Total | C36: Done | D36: In Process | E36: New | F36: Completion %
A37: W19 | B37: =COUNTIF(Tasks!K2:K1000,A37) | C37: =COUNTIFS(Tasks!K2:K1000,A37,Tasks!G2:G1000,"Done") | D37: =COUNTIFS(Tasks!K2:K1000,A37,Tasks!G2:G1000,"In process") | E37: =COUNTIFS(Tasks!K2:K1000,A37,Tasks!G2:G1000,"New") | F37: =IFERROR(C37/B37,0)
A38: W21 | B38: =COUNTIF(Tasks!K2:K1000,A38) | C38: =COUNTIFS(Tasks!K2:K1000,A38,Tasks!G2:G1000,"Done") | D38: =COUNTIFS(Tasks!K2:K1000,A38,Tasks!G2:G1000,"In process") | E38: =COUNTIFS(Tasks!K2:K1000,A38,Tasks!G2:G1000,"New") | F38: =IFERROR(C38/B38,0)
A39: W23 | B39: =COUNTIF(Tasks!K2:K1000,A39) | C39: =COUNTIFS(Tasks!K2:K1000,A39,Tasks!G2:G1000,"Done") | D39: =COUNTIFS(Tasks!K2:K1000,A39,Tasks!G2:G1000,"In process") | E39: =COUNTIFS(Tasks!K2:K1000,A39,Tasks!G2:G1000,"New") | F39: =IFERROR(C39/B39,0)
A42: Weekly Performance by Employee — Completion %
A43: PIC | B43: W19 | C43: W21 | D43: W23
A44: Ahad | B44: =IFERROR(COUNTIFS(Tasks!D2:D1000,$A44,Tasks!K2:K1000,B$43,Tasks!G2:G1000,"Done")/COUNTIFS(Tasks!D2:D1000,$A44,Tasks!K2:K1000,B$43),0) | C44: =IFERROR(COUNTIFS(Tasks!D2:D1000,$A44,Tasks!K2:K1000,C$43,Tasks!G2:G1000,"Done")/COUNTIFS(Tasks!D2:D1000,$A44,Tasks!K2:K1000,C$43),0) | D44: =IFERROR(COUNTIFS(Tasks!D2:D1000,$A44,Tasks!K2:K1000,D$43,Tasks!G2:G1000,"Done")/COUNTIFS(Tasks!D2:D1000,$A44,Tasks!K2:K1000,D$43),0)
A45: Arslan | B45: =IFERROR(COUNTIFS(Tasks!D2:D1000,$A45,Tasks!K2:K1000,B$43,Tasks!G2:G1000,"Done")/COUNTIFS(Tasks!D2:D1000,$A45,Tasks!K2:K1000,B$43),0) | C45: =IFERROR(COUNTIFS(Tasks!D2:D1000,$A45,Tasks!K2:K1000,C$43,Tasks!G2:G1000,"Done")/COUNTIFS(Tasks!D2:D1000,$A45,Tasks!K2:K1000,C$43),0) | D45: =IFERROR(COUNTIFS(Tasks!D2:D1000,$A45,Tasks!K2:K1000,D$43,Tasks!G2:G1000,"Done")/COUNTIFS(Tasks!D2:D1000,$A45,Tasks!K2:K1000,D$43),0)
A46: Moahed | B46: =IFERROR(COUNTIFS(Tasks!D2:D1000,$A46,Tasks!K2:K1000,B$43,Tasks!G2:G1000,"Done")/COUNTIFS(Tasks!D2:D1000,$A46,Tasks!K2:K1000,B$43),0) | C46: =IFERROR(COUNTIFS(Tasks!D2:D1000,$A46,Tasks!K2:K1000,C$43,Tasks!G2:G1000,"Done")/COUNTIFS(Tasks!D2:D1000,$A46,Tasks!K2:K1000,C$43),0) | D46: =IFERROR(COUNTIFS(Tasks!D2:D1000,$A46,Tasks!K2:K1000,D$43,Tasks!G2:G1000,"Done")/COUNTIFS(Tasks!D2:D1000,$A46,Tasks!K2:K1000,D$43),0)
A47: Moahed - Victory | B47: =IFERROR(COUNTIFS(Tasks!D2:D1000,$A47,Tasks!K2:K1000,B$43,Tasks!G2:G1000,"Done")/COUNTIFS(Tasks!D2:D1000,$A47,Tasks!K2:K1000,B$43),0) | C47: =IFERROR(COUNTIFS(Tasks!D2:D1000,$A47,Tasks!K2:K1000,C$43,Tasks!G2:G1000,"Done")/COUNTIFS(Tasks!D2:D1000,$A47,Tasks!K2:K1000,C$43),0) | D47: =IFERROR(COUNTIFS(Tasks!D2:D1000,$A47,Tasks!K2:K1000,D$43,Tasks!G2:G1000,"Done")/COUNTIFS(Tasks!D2:D1000,$A47,Tasks!K2:K1000,D$43),0)
A48: Victory | B48: =IFERROR(COUNTIFS(Tasks!D2:D1000,$A48,Tasks!K2:K1000,B$43,Tasks!G2:G1000,"Done")/COUNTIFS(Tasks!D2:D1000,$A48,Tasks!K2:K1000,B$43),0) | C48: =IFERROR(COUNTIFS(Tasks!D2:D1000,$A48,Tasks!K2:K1000,C$43,Tasks!G2:G1000,"Done")/COUNTIFS(Tasks!D2:D1000,$A48,Tasks!K2:K1000,C$43),0) | D48: =IFERROR(COUNTIFS(Tasks!D2:D1000,$A48,Tasks!K2:K1000,D$43,Tasks!G2:G1000,"Done")/COUNTIFS(Tasks!D2:D1000,$A48,Tasks!K2:K1000,D$43),0)

Sheet Sheet

Sheet Tasks
A1: Open Time | B1: Module | C1: Question | D1: PIC | E1: Management Action | F1: Completion Time | G1: Status | H1: Remarks | I1: Description | J1: New Tasks | K1: Source Week | L1: Done? (✓)
A2: 0607 | B2: TEC | C2: Training CC | D2: Ahad | E2: Complete CC Training | F2: Monthly | G2: In process | H2: Plan1/Completed 0) | I2: CC Refreshment Training will be on 22 June. | K2: W23 | L2: FALSE
A3: 0419 | B3: TEC | C3: Training New model | D3: Ahad | E3: Floor Standing Training Materials update | F3: 2026-04-30 | G3: Done | H3: Training PPT Update in progress. | J3: Check with HQ for the training meterial | K3: W19 | L3: TRUE
A4: 0426 | B4: TEC | C4: Training Online | D4: Ahad | E4: 1.ABL Service Centers( Including Floor Standing ) 2. | F4: 2026-05-07 | G4: In process | H4: Offline Training 17th May | I4: To be conduct in Jeddah - Arrange food & Claim Take photos | J4: Check for Dammam Staff to come to Riyadh | K4: W19 | L4: FALSE
A5: 0503 | B5: TEC | C5: Training Online | D5: Ahad | E5: 1.Training plan for UAE | F5: 2026-05-31 | G5: In process | H5: Offline Training | I5: Conduct Offline training in UAE - Discuss with Hassaib Monday - 4th may | K5: W21 | L5: FALSE
A6: 0426 | B6: TEC | C6: Installation Training | D6: Ahad | E6: Installtion Training for Sales Dealers Teams in Qassim City. | F6: 2026-04-30 | G6: In process | H6: 0 times / plan 1 times; Communicating with Mr.Alaa for Installation Training in Qassim City in Next week.Instead Training will be done for Riyadh Installation teams. | I6: To be confirmed Next Week | K6: W19 | L6: FALSE
A7: 0518 | B7: TEC | C7: Technical Support | D7: Ahad | E7: Floor standing unit repair technicial support | F7: 2026-04-30 | G7: Done | H7: 1 / 1 WOs Received | I7: work order:GD20260511315458 has been followed online and closed as value added in Jeddah city. | K7: W23 | L7: TRUE
A8: 0607 | B8: Qulity | C8: FG Inspection | D8: Ahad | E8: Complete Onsite FG Inspection activity | F8: Monthly | G8: In process | H8: 0 sets / plan 5 sets | I8: will be inspect after New shipment will recieved on 12th june | K8: W23 | L8: FALSE
A9: 0607 | B9: Qulity | C9: Installation | D9: Ahad | E9: Complete Onsite Installation Inspection activity | F9: Monthly | G9: In process | H9: 0 units / plan 10 units | I9: Installation will be follow up after sales team confirmation. | K9: W23 | L9: FALSE
A10: 0531 | B10: Qulity | C10: Defective parts | D10: Ahad | E10: Complete Defected Parts Report | F10: Monthly | G10: Done | H10: 24 reported / 28 received | I10: Waiting for 2 PCB ,parts returned which consumed during month of May. | J10: 2 parts on the way 24-May | K10: W23 | L10: TRUE
A11: 0419 | B11: SP | C11: SP new modle | D11: Arslan | E11: New Models 2026 SP stock | F11: Monthly | G11: In process | H11: Total Models 55 In Aux Saudi / S.Parts Not available for 33 Models. ordered for 10 models now remaining 23 | K11: W23 | L11: FALSE
A12: 0426 | B12: SP | C12: SP lists | D12: Arslan | E12: 55 models' spare part lists and explored views | F12: 2026-05-30 | G12: In process | H12: 55 Models | I12: full list will all spare parts | K12: W21 | L12: FALSE
A13: 0419 | B13: SP | C13: SP PO | D13: Arslan | E13: Q1 PO#1 & #2 ready, pending shipment | F13: 2026-04-30 | G13: In process | H13: Shipment is ready for dispatched ETA will updated From HQ | K13: W21 | L13: FALSE
A14: 0419 | B14: SP | C14: SP physical count | D14: Arslan | E14: SP physical count report | F14: Monthly | G14: Done | H14: 10 / 10 Parts | K14: W23 | L14: TRUE
A15: 0419 | B15: SP | C15: SP inventory in SVCs | D15: Arslan | E15: Replenish Safety stock to (Wifex - Classic ) | F15: 2026-04-30 | G15: Done | H15: Done | K15: W23 | L15: TRUE
A16: 0419 | B16: SP | C16: SP Defectives | D16: Arslan | E16: Collect Defected Parts | F16: Monthly | G16: In process | H16: 28 received / 30 Pcs Actual /02 Pics need to collect | I16: 02 remaining to collect emails send to SVC will be collected this week delay beacuse of EID holidays | K16: W23 | L16: FALSE
A17: 0419 | B17: SP | C17: SP FFR 24H | D17: Arslan | E17: SP Delivery within 24H | F17: Monthly | G17: Done | H17: 29 Delivered / 29 Requets | K17: W23 | L17: TRUE
A18: 0419 | B18: SP | C18: SP Inbound | D18: Arslan | E18: Inbound Feb shipement on GCSS | F18: 2026-04-30 | G18: In process | H18: 4630 inbounded / 4690 received | I18: 30 Pcs PCB for 11222004001632 ODU PCB is remaining | J18: Packing Meterial - need to remove from system & disposal | K18: W23 | L18: FALSE
A19: 0426 | B19: SP | C19: SP liquidation | D19: Arslan | E19: package material liquidation | F19: 2026-05-30 | G19: In process | H19: - 26 Parts list ready for approvel - Include new packing meterial list | I19: Send for approvel to Mr. Victory | K19: W23 | L19: FALSE
A20: 0517 | B20: CC | C20: CC Evalauation | D20: Moahed | E20: CC agents Evaluation report | F20: Monthly | G20: In process | H20: To be shared 7th Jun | I20: To be shared Today | K20: W23 | L20: FALSE
A21: 0419 | B21: CC | C21: UAE Support | D21: Moahed | E21: Evaluate the perfomance of UAE 3rd Party Call Center agency | F21: 2026-05-04 | G21: Done | H21: Complated - Haseeb shared his ID | J21: shift of May to June | K21: W21 | L21: TRUE
A22: 0426 | B22: CC | C22: Agent shift | D22: Moahed | E22: CC agents shift in May to June | F22: 2026-05-07 | G22: Done | H22: 25th Jun ~ 15th Jul initially | K22: W21 | L22: TRUE
A23: 0419 | B23: SN | C23: SVC Network | D23: Moahed | E23: Complaete ABL Training on order dispatch and accept | F23: 2026-04-30 | G23: Done | H23: Complated | K23: W21 | L23: TRUE
A24: 0419 | B24: SN | C24: SVC Network | D24: Moahed | E24: Send Test Order to ABL | F24: 2026-04-30 | G24: Done | H24: Complated | K24: W21 | L24: TRUE
A25: 0426 | B25: SN | C25: New ASP | D25: Moahed | E25: 3 New ASP discussion | F25: 2026-06-30 | G25: In process | H25: 1 Shared Contract - 2 Pending | I25: 1 MDM Complated - Waiting other new ASP to share Data | J25: CHeck MDM Account | K25: W23 | L25: FALSE
A26: 0503 | C26: SVC Network | D26: Moahed | E26: Auto Update for Dashboard | F26: 2026-06-30 | G26: In process | H26: Collect the data from HQ auto to the dashboard | I26: Pending for Meeting with HQ | K26: W23 | L26: FALSE
A27: 0419 | B27: SN | C27: SVC Network | D27: Moahed | E27: Complate the Warranty payment to ASC | F27: 2026-04-30 | G27: Done | H27: Complated | K27: W21 | L27: TRUE
A28: 0406 | B28: SN | C28: SVC Network | D28: Moahed | E28: Share The warranty Payment slip for Mar | F28: 2026-05-07 | G28: Done | H28: Complated | K28: W21 | L28: TRUE
A29: 0406 | B29: SN | C29: SVC Network | D29: Moahed | E29: Update the ASC Details on GCSS System | F29: 2026-05-07 | G29: Done | H29: Complated | K29: W21 | L29: TRUE
A30: 0406 | B30: SN | C30: SVC Network | D30: Moahed | E30: Start the process of Warranty orders | F30: 2026-06-30 | G30: In process | H30: 3 Payment Uploaded - 1 pending for sharing the invoice ( Wifex ) | I30: Share the confirmed list | K30: W23 | L30: FALSE
A31: 0511 | B31: SN | C31: WO dispatch | D31: Moahed | E31: Floor standing work order dispatch SVCs, labor price discussion Classic & ZAM WIFIX | F31: 2026-06-30 | G31: Done | H31: One order dispatched and we will pay the same labor fee for now | I31: 1 received | K31: W23 | L31: TRUE
A32: 0426 | B32: SN | C32: Labor fee | D32: Moahed - Victory | E32: Commerical AC & Floor standing | F32: 2026-06-30 | G32: In process | I32: Excel file is ready pending for system update | K32: W23 | L32: FALSE
A33: 0426 | B33: SN | C33: ASP Settlement | D33: Victory | E33: online payment operation | F33: 2026-05-30 | G33: New | H33: Under checking with IT | K33: W19 | L33: FALSE
A34: 0419 | B34: IT | C34: GCSS system | D34: Victory | E34: GCSS improvement requirements & follow up total18 | F34: Monthly | G34: In process | H34: 6 done / 12 in process Total 18 | I34: Before jun HQ will complate 3 | K34: W23 | L34: FALSE
A35: 0426 | B35: SN | C35: New ASP | D35: Victory | E35: Sign New contract for HLM | F35: 2026-06-30 | G35: In process | H35: Check with Jon | K35: W19 | L35: FALSE
A36: 0426 | B36: TEC | C36: Training Online | D36: Ahad | E36: 1.ABL Service Centers( Including Floor Standing ) | F36: 2026-05-17 | G36: In process | H36: Offline Training 17th May | I36: To be conduct in Jeddah - Arrange food & Claim Take photos | J36: Dammam Staff came to Riyadh | K36: W21 | L36: FALSE
A37: 0426 | B37: TEC | C37: Installation Training | D37: Ahad | E37: Installtion Training for Sales Dealers Teams in Riyadh | F37: 2026-05-31 | G37: In process | H37: 0 times / plan 1 times. | I37: As per Sales team New Installation companies Registration in progress.Hopefully we can conduct Installation Training in Next Week. | K37: W21 | L37: FALSE
A38: 0511 | B38: SP | C38: SP PO | D38: Arslan | E38: Request GOA replacement request for - AUX19HQCA 1 unit & AUX19CQA 1 unit | F38: 2026-05-11 | G38: Done | H38: Apply in GOA its approved | K38: W23 | L38: TRUE
A39: 0511 | B39: SP | C39: SP inventory in SVCs | D39: Arslan | E39: Supply safety stock for ABL | F39: 2026-06-15 | G39: In process | H39: Safety Stock List is ready will be dispatched after Eid holidays | K39: W23 | L39: FALSE
A40: 0511 | B40: SN | C40: Call Center | D40: Moahed | E40: Check AI agent task and cost | F40: 2026-05-31 | G40: Done | H40: Cost will be 1035 Agent for 5000 Credit | I40: test the lowest version - for after working hours | K40: W23 | L40: TRUE
...

Sheet How to Use
A1: How to Use This Dashboard
A3: 1. Go to the 'Tasks' sheet to edit task data.
A4: 2. The 'Status' column has a dropdown — pick Done / In process / New.
A5: 3. The 'Done? (✓)' column toggles TRUE/FALSE — TRUE strikes through the row.
A6: 4. All KPIs, charts and trend tables on 'Dashboard' update automatically.
A7: 5. Use the filter buttons on the Tasks table to slice by PIC, Module, Week, Status.
A8: 6. Weekly Trend section compares W19 / W21 / W23 progress side by side.
A9: 7. Employee × Week heat matrix shows performance progression per person.
A11: Color legend:
A12: Green = Done Yellow = In process Red = New / Pending
